[2017-02-09 16:08:30 +0300] [2031] [INFO] Starting gunicorn 19.6.0
[2017-02-09 16:08:30 +0300] [2031] [INFO] Listening at: http://0.0.0.0:8000 (2031)
[2017-02-09 16:08:30 +0300] [2031] [INFO] Using worker: sync
[2017-02-09 16:08:30 +0300] [2034] [INFO] Booting worker with pid: 2034
[2017-02-09 16:08:31 +0300] [2034] [ERROR] Exception in worker process
Traceback (most recent call last):
  File "/usr/local/lib/python3.5/dist-packages/gunicorn/arbiter.py", line 557, in spawn_worker
    worker.init_process()
  File "/usr/local/lib/python3.5/dist-packages/gunicorn/workers/base.py", line 126, in init_process
    self.load_wsgi()
  File "/usr/local/lib/python3.5/dist-packages/gunicorn/workers/base.py", line 136, in load_wsgi
    self.wsgi = self.app.wsgi()
  File "/usr/local/lib/python3.5/dist-packages/gunicorn/app/base.py", line 67, in wsgi
    self.callable = self.load()
  File "/usr/local/lib/python3.5/dist-packages/gunicorn/app/wsgiapp.py", line 65, in load
    return self.load_wsgiapp()
  File "/usr/local/lib/python3.5/dist-packages/gunicorn/app/wsgiapp.py", line 52, in load_wsgiapp
    return util.import_app(self.app_uri)
  File "/usr/local/lib/python3.5/dist-packages/gunicorn/util.py", line 357, in import_app
    __import__(module)
  File "/home/jonny/web/box/web/ask/ask/wsgi.py", line 16, in <module>
    application = get_wsgi_application()
  File "/usr/local/lib/python3.5/dist-packages/django/core/wsgi.py", line 13, in get_wsgi_application
    django.setup(set_prefix=False)
  File "/usr/local/lib/python3.5/dist-packages/django/__init__.py", line 22, in setup
    configure_logging(settings.LOGGING_CONFIG, settings.LOGGING)
  File "/usr/local/lib/python3.5/dist-packages/django/conf/__init__.py", line 53, in __getattr__
    self._setup(name)
  File "/usr/local/lib/python3.5/dist-packages/django/conf/__init__.py", line 41, in _setup
    self._wrapped = Settings(settings_module)
  File "/usr/local/lib/python3.5/dist-packages/django/conf/__init__.py", line 97, in __init__
    mod = importlib.import_module(self.SETTINGS_MODULE)
  File "/usr/lib/python3.5/importlib/__init__.py", line 126, in import_module
    return _bootstrap._gcd_import(name[level:], package, level)
ImportError: No module named 'ask.settings'
[2017-02-09 16:08:31 +0300] [2034] [INFO] Worker exiting (pid: 2034)
[2017-02-09 16:08:31 +0300] [2031] [INFO] Shutting down: Master
[2017-02-09 16:08:31 +0300] [2031] [INFO] Reason: Worker failed to boot.
